<?xml version="1.0" encoding="UTF-8"?>
<robot xmlns:xacro="http://www.ros.org/wiki/xacro">

	<xacro:macro name="simple_gripper" params="prefix parent">
		<joint name="${prefix}gripper_base_joint" type="fixed">
			<parent link="${parent}" />
			<child link="${prefix}gripper_base" />
			<origin xyz="0 0 0" rpy="0 0 0" />
		</joint>

		<!-- Gripper Base -->
		<link name="${prefix}gripper_base">
			<xacro:default_inertial />
			<visual>
				<origin xyz="0 0 0.005" rpy="0 0 0" />
				<geometry>
					<box size="0.04 0.05 0.01" />
				</geometry>
				<material name="Grey" />
			</visual>
			<collision>
				<origin xyz="0 0 0.005" rpy="0 0 0" />
				<geometry>
					<box size="0.04 0.05 0.01" />
				</geometry>
			</collision>
		</link>
		<gazebo reference="${prefix}gripper_base">
			<material>Gazebo/Grey</material>
		</gazebo>

		<!-- Right Finger -->
		<joint name="${prefix}finger_right_joint" type="prismatic">
			<parent link="${prefix}gripper_base" />
			<child link="${prefix}finger_right" />
			<origin xyz="0 0.0 0.0" rpy="0 0 0" />
			<axis xyz="0 -1 0" />
			<limit lower="0.0" upper="0.02" effort="10.0" velocity="0.05" />
		</joint>
		<link name="${prefix}finger_right">
			<xacro:default_inertial />
			<visual>
				<origin xyz="0 -0.005 0.02" rpy="0 0 0" />
				<geometry>
					<box size="0.02 0.01 0.02" />
				</geometry>
				<material name="White" />
			</visual>
			<collision>
				<origin xyz="0 -0.005 0.02" rpy="0 0 0" />
				<geometry>
					<box size="0.02 0.01 0.02" />
				</geometry>
			</collision>
		</link>
		<gazebo reference="${prefix}finger_right">
			<material>Gazebo/White</material>
		</gazebo>

		<!-- Left Finger -->
		<joint name="${prefix}finger_left_joint" type="prismatic">
			<parent link="${prefix}gripper_base" />
			<child link="${prefix}finger_left" />
			<origin xyz="0 0 0.0" rpy="0 0 0" />
			<axis xyz="0 1 0" />
			<limit lower="0.0" upper="0.02" effort="10.0" velocity="0.05" />
		</joint>
		<link name="${prefix}finger_left">
			<xacro:default_inertial />
			<visual>
				<origin xyz="0 0.005 0.02" rpy="0 0 0" />
				<geometry>
					<box size="0.02 0.01 0.02" />
				</geometry>
				<material name="White" />
			</visual>
			<collision>
				<origin xyz="0 0.005 0.02" rpy="0 0 0" />
				<geometry>
					<box size="0.02 0.01 0.02" />
				</geometry>
			</collision>
		</link>
		<gazebo reference="${prefix}finger_left">
			<material>Gazebo/White</material>
		</gazebo>

		<joint name="${prefix}grasp_point_joint" type="fixed">
			<parent link="${prefix}gripper_base" />
			<child link="${prefix}grasp_point" />
			<origin xyz="0 0 0.02" rpy="0 0 0" />
		</joint>
		<link name="${prefix}grasp_point" />

	</xacro:macro>
</robot>