<?xml version="1.0" encoding="UTF-8"?>
<robot xmlns:xacro="http://www.ros.org/wiki/xacro">

  <xacro:macro name="stanford_robot" params="prefix parent *origin">

    <joint name="${prefix}base_joint" type="fixed">
      <xacro:insert_block name="origin" />
      <parent link="${parent}" />
      <child link="${prefix}base_link" />
    </joint>

    <link name="${prefix}base_link">
      <xacro:default_inertial />
      <visual>
        <origin xyz="0 0 0.005" rpy="0 0 0" />
        <geometry>
          <box size="0.15 0.15 0.01" />
        </geometry>
        <material name="Violet" />
      </visual>
      <collision>
        <origin xyz="0 0 0.005" rpy="0 0 0" />
        <geometry>
          <box size="0.15 0.15 0.01" />
        </geometry>
      </collision>
    </link>
    <gazebo reference="${prefix}base_link">
      <material>Gazebo/Orange</material>
    </gazebo>

    <joint name="${prefix}joint_1" type="revolute">
      <parent link="${prefix}base_link" />
      <child link="${prefix}link_0" />
      <origin xyz="0 0 0.01" rpy="0 0 0" />
      <axis xyz="0 0 1" />
      <limit effort="1000" velocity="${radians(180)}" lower="-3.1416" upper="3.1416" />
    </joint>

    <link name="${prefix}link_0">
      <xacro:default_inertial />
      <visual>
        <origin xyz="0 0 0.15" rpy="0 0 0" />
        <geometry>
          <cylinder radius="0.025" length="0.30" />
        </geometry>
        <material name="Blue" />
      </visual>
      <collision>
        <origin xyz="0 0 0.15" rpy="0 0 0" />
        <geometry>
          <cylinder radius="0.025" length="0.30" />
        </geometry>
      </collision>
    </link>
    <gazebo reference="${prefix}link_0">
      <material>Gazebo/Orange</material>
    </gazebo>

    <!-- Joint 2 Revolute about Y, between link_0 and link_1 -->
    <joint name="${prefix}joint_2" type="revolute">
      <parent link="${prefix}link_0" />
      <child link="${prefix}link_1" />
      <origin xyz="0 0.05 0.275" rpy="0 ${radians(60)} 0" />
      <axis xyz="0 1 0" />
      <limit effort="1000" velocity="${radians(180)}" lower="-3.1416" upper="3.1416" />
    </joint>

    <!-- Link 1 -->
    <link name="${prefix}link_1">
      <xacro:default_inertial />
      <visual>
        <origin xyz="0 0 0.0" rpy="0 0 0" />
        <geometry>
          <box size="0.05 0.05 0.10" />
        </geometry>
        <material name="Green" />
      </visual>
      <collision>
        <origin xyz="0 0.05 0.0" rpy="0 0 0" />
        <geometry>
          <box size="0.05 0.05 0.10" />
        </geometry>
      </collision>
    </link>
    <gazebo reference="${prefix}link_1">
      <material>Gazebo/Blue</material>
    </gazebo>

    <!-- Joint 3 直動リンク Prismatic -->
    <joint name="${prefix}joint_3" type="prismatic">
      <parent link="${prefix}link_1" />
      <child link="${prefix}link_2" />
      <origin xyz="0 0 0.0" rpy="0 0 0" />
      <axis xyz="0 0 1" />
      <limit effort="1000.0" velocity="0.3" lower="-0.2" upper="0.2" />
    </joint>

    <!-- Link 2 -->
    <link name="${prefix}link_2">
      <xacro:default_inertial />
      <visual>
        <origin xyz="0 0 0" rpy="0 0 0" />
        <geometry>
          <box size="0.03 0.03 0.50" />
        </geometry>
        <material name="Red" />
      </visual>
      <collision>
        <origin xyz="0 0 0.0" rpy="0 0 0" />
        <geometry>
          <box size="0.03 0.03 0.50" />
        </geometry>
      </collision>
    </link>
    <gazebo reference="${prefix}link_2">
      <material>Gazebo/Yellow</material>
    </gazebo>

    <!-- Joint 4 Revolute about Z, between link_2 and link_3 -->
    <joint name="${prefix}joint_4" type="revolute">
      <parent link="${prefix}link_2" />
      <child link="${prefix}link_3" />
      <origin xyz="0 0 0.25" rpy="0 0 0" />
      <axis xyz="0 0 1" />
      <limit effort="1000" velocity="${radians(180)}" lower="-3.1416" upper="3.1416" />
    </joint>

    <!-- Link 3 -->
    <link name="${prefix}link_3">
      <xacro:default_inertial />
      <visual>
        <origin xyz="0 0 0.02" rpy="0 0 0" />
        <geometry>
          <cylinder radius="0.025" length="0.04" />
        </geometry>
        <material name="Gray" />
      </visual>
      <collision>
        <origin xyz="0 0 0.02" rpy="0 0 0" />
        <geometry>
          <cylinder radius="0.025" length="0.04" />
        </geometry>
      </collision>
    </link>
    <gazebo reference="${prefix}link_3">
      <material>Gazebo/Green</material>
    </gazebo>

    <!-- Joint 5 Revolute about Y, between link_3 and link_4 -->
    <joint name="${prefix}joint_5" type="revolute">
      <parent link="${prefix}link_3" />
      <child link="${prefix}link_4" />
      <origin xyz="0 0 0.04" rpy="0 ${radians(90)} 0" />
      <axis xyz="0 1 0" />
      <limit effort="1000" velocity="${radians(180)}" lower="-3.1416" upper="3.1416" />
    </joint>

    <!-- Link 4 -->
    <link name="${prefix}link_4">
      <xacro:default_inertial />
      <visual>
        <origin xyz="0 0 0.02" rpy="0 0 0" />
        <geometry>
          <box size="0.03 0.02 0.04" />
        </geometry>
        <material name="White" />
      </visual>
      <collision>
        <origin xyz="0 0 0.02" rpy="0 0 0" />
        <geometry>
          <box size="0.03 0.02 0.04" />
        </geometry>
      </collision>
    </link>
    <gazebo reference="${prefix}link_4">
      <material>Gazebo/Red</material>
    </gazebo>

    <!-- Joint 6 Revolute (wrist), between link_4 and flange -->
    <joint name="${prefix}joint_6" type="revolute">
      <parent link="${prefix}link_4" />
      <child link="${prefix}link_5" />
      <origin xyz="0 0 0.04" rpy="0 0 0" />
      <axis xyz="0 0 1" />
      <limit effort="30.0" velocity="${radians(180)}" lower="-3.1416" upper="3.1416" />
    </joint>

    <!-- Flange Link (Link 5) -->
    <link name="${prefix}link_5">
      <xacro:default_inertial />
      <visual>
        <origin xyz="0 0 0.005" rpy="0 0 0" />
        <geometry>
          <cylinder radius="0.025" length="0.01" />
        </geometry>
        <material name="Black" />
      </visual>
      <collision>
        <origin xyz="0 0 0.005" rpy="0 0 0" />
        <geometry>
          <cylinder radius="0.025" length="0.01" />
        </geometry>
      </collision>
    </link>
    <gazebo reference="${prefix}link_5">
      <material>Gazebo/White</material>
    </gazebo>


    <!-- 実機での作業点と一致するTOOLフレームの定義、エンドエフェクタ制御用フレーム -->
    <!-- 実体なし、TFツリーやMoveItとの整合のために非常に重要 -->
    <link name="${prefix}tool0" />

    <!-- Flange Link -->
    <!-- ツール（グリッパ、吸着パッドなど）を取り付ける標準フレーム -->
    <!-- REP 103準拠でX+軸がツール取付方向（前方）を向く -->
    <link name="${prefix}flange" />

    <!-- 実機制御器とURDFの原点を一致させるための基準フレーム -->
    <!-- ROS-I仕様の標準、制御器の「ベース」座標に対応 -->
    <link name="${prefix}base" />

    <!-- tool joint - fixed -->
    <joint name="${prefix}tool_joint" type="fixed">
      <parent link="${prefix}link_5" />
      <child link="${prefix}tool0" />
      <!-- <origin xyz="0 0 0.01" rpy="0 ${-pi} ${pi/2}" /> -->
      <origin xyz="0 0 0.01" rpy="0 0 0" />
    </joint>

    <!-- base joint - fixed -->
    <joint name="${prefix}base_link-base_joint" type="fixed">
      <origin xyz="0 0 0" rpy="0 0 0" />
      <parent link="${prefix}base_link" />
      <child link="${prefix}base" />
    </joint>

    <!-- flange joint - fixed -->
    <joint name="${prefix}tool0-flange_joint" type="fixed">
      <origin xyz="0 0 0" rpy="0 0 0" />
      <parent link="${prefix}tool0" />
      <child link="${prefix}flange" />
    </joint>

  </xacro:macro>

</robot>