<?xml version="1.0" encoding="UTF-8"?>
<robot xmlns:xacro="http://www.ros.org/wiki/xacro">

  <xacro:include filename="$(find sushi_bot_description)/urdf/common.xacro" />

  <!-- ※ *がついたパラメータはブロックパラメータ -->

  <xacro:macro name="sushi_bot" params="prefix parent *origin">
    <!-- LINKS -->
    <!-- base link -->
    <link name="${prefix}base_link">
      <xacro:default_inertial />
      <visual>
        <origin xyz="0 0 0.05" rpy="0 0 0" />
        <geometry>
          <box size="0.3 0.3 0.1" />
        </geometry>
        <material name="StoglRobotics/Violet" />
      </visual>
      <collision>
        <origin xyz="0 0 0.05" rpy="0 0 0" />
        <geometry>
          <box size="0.3 0.3 0.1" />
        </geometry>
      </collision>
    </link>
    <gazebo reference="${prefix}base_link">
      <material>Gazebo/Orange</material>
    </gazebo>


    <!-- link 1 -->
    <link name="${prefix}link1">
      <!-- Default inertial for Gazebo - copy and edit block from 'common.xacro'
           to get more realistic behaviour-->
      <xacro:default_inertial />
      <visual>
        <origin xyz="0 0 0.25" rpy="0 0 0" />
        <geometry>
          <cylinder length="0.5" radius="${0.2/2}" />
        </geometry>
        <material name="StoglRobotics/DarkGrey" />
      </visual>
      <collision>
        <origin xyz="0 0 0.25" rpy="0 0 0" />
        <geometry>
          <cylinder length="0.5" radius="${0.2/2}" />
        </geometry>
      </collision>
    </link>
    <gazebo reference="${prefix}link1">
      <material>Gazebo/Black</material>
    </gazebo>

    <!-- link 2 -->
    <link name="${prefix}link2">
      <!-- Default inertial for Gazebo - copy and edit block from 'common.xacro'
           to get more realistic behaviour-->
      <xacro:default_inertial />
      <visual>
        <origin xyz="0 0 0.3" rpy="0 0 0" />
        <geometry>
          <box size="0.1 0.1 0.6" />
        </geometry>
        <material name="StoglRobotics/LightGrey" />
      </visual>
      <collision>
        <origin xyz="0 0 0.3" rpy="0 0 0" />
        <geometry>
          <box size="0.1 0.1 0.6" />
        </geometry>
      </collision>
    </link>
    <gazebo reference="${prefix}link2">
      <material>Gazebo/Gray</material>
    </gazebo>

    <!-- 座標マーカー的な ~~~ -->
    <!-- 共通して固定ジョイントで親リンクに接続される。 -->

    <!-- 実機での作業点と一致するTOOLフレームの定義、エンドエフェクタ制御用フレーム -->
    <!-- 実体なし、TFツリーやMoveItとの整合のために非常に重要 -->
    <link name="${prefix}tool0" />

    <!-- 実機制御器とURDFの原点を一致させるための基準フレーム -->
    <!-- ROS-I仕様の標準、制御器の「ベース」座標に対応 -->
    <link name="${prefix}base" />

    <!-- ツール（グリッパ、吸着パッドなど）を取り付ける標準フレーム -->
    <!-- REP 103準拠でX+軸がツール取付方向（前方）を向く -->
    <link name="${prefix}flange" />

    <!-- ~~~ -->

    <!-- END LINKS -->

    <!-- JOINTS -->
    <!-- base_joint fixes base_link to the environment -->
    <joint name="${prefix}base_joint" type="fixed">
      <!-- ブロック *origin を挿入 -->
      <xacro:insert_block name="origin" />
      <parent link="${parent}" />
      <child link="${prefix}base_link" />
    </joint>

    <!-- joint1 -->
    <joint name="${prefix}joint1" type="revolute">
      <origin xyz="0 0 0.1" rpy="0 0 0" />
      <parent link="${prefix}base_link" />
      <child link="${prefix}link1" />
      <axis xyz="0 0 1" />
      <limit effort="1000" lower="${radians(-380)}" upper="${radians(380)}"
        velocity="${radians(180)}" />
    </joint>

    <!-- joint2 -->
    <joint name="${prefix}joint2" type="revolute">
      <origin xyz="0 0 0.5" rpy="0 -${pi/2} 0" />
      <parent link="${prefix}link1" />
      <child link="${prefix}link2" />
      <axis xyz="0 1 0" />
      <limit effort="1000" lower="${radians(-60)}" upper="${radians(240)}"
        velocity="${radians(180)}" />
    </joint>

    <!-- tool joint - fixed -->
    <joint name="${prefix}tool_joint" type="fixed">
      <parent link="${prefix}link2" />
      <child link="${prefix}tool0" />
      <origin xyz="0 0 0.6" rpy="0 ${-pi} ${pi/2}" />
    </joint>

    <!-- base joint - fixed -->
    <joint name="${prefix}base_link-base_joint" type="fixed">
      <origin xyz="0 0 0" rpy="0 0 0" />
      <parent link="${prefix}base_link" />
      <child link="${prefix}base" />
    </joint>

    <!-- flange joint - fixed -->
    <joint name="${prefix}tool0-flange_joint" type="fixed">
      <origin xyz="0 0 0" rpy="0 0 0" />
      <parent link="${prefix}tool0" />
      <child link="${prefix}flange" />
    </joint>

    <!-- END JOINTS -->
  </xacro:macro>

</robot>